Workbook

Sheet Summary
A1: Subject | B1: Subtopics | C1: Pearl listings | D1: Unique pearls | E1: Cross-listed pearls
A2: Anatomy | B2: =COUNTIFS('All Pearls'!$A$2:$A$2690,A2,'All Pearls'!$H$2:$H$2690,1) -> 10 | C2: =COUNTIF('All Pearls'!$A$2:$A$2690,A2) -> 173 | D2: =COUNTIFS('All Pearls'!$A$2:$A$2690,A2,'All Pearls'!$G$2:$G$2690,1) -> 168 | E2: =C2-D2 -> 5
A3: Physiology | B3: =COUNTIFS('All Pearls'!$A$2:$A$2690,A3,'All Pearls'!$H$2:$H$2690,1) -> 12 | C3: =COUNTIF('All Pearls'!$A$2:$A$2690,A3) -> 208 | D3: =COUNTIFS('All Pearls'!$A$2:$A$2690,A3,'All Pearls'!$G$2:$G$2690,1) -> 206 | E3: =C3-D3 -> 2
A4: Biochemistry | B4: =COUNTIFS('All Pearls'!$A$2:$A$2690,A4,'All Pearls'!$H$2:$H$2690,1) -> 11 | C4: =COUNTIF('All Pearls'!$A$2:$A$2690,A4) -> 139 | D4: =COUNTIFS('All Pearls'!$A$2:$A$2690,A4,'All Pearls'!$G$2:$G$2690,1) -> 132 | E4: =C4-D4 -> 7
A5: Pathology | B5: =COUNTIFS('All Pearls'!$A$2:$A$2690,A5,'All Pearls'!$H$2:$H$2690,1) -> 12 | C5: =COUNTIF('All Pearls'!$A$2:$A$2690,A5) -> 257 | D5: =COUNTIFS('All Pearls'!$A$2:$A$2690,A5,'All Pearls'!$G$2:$G$2690,1) -> 255 | E5: =C5-D5 -> 2
A6: Pharmacology | B6: =COUNTIFS('All Pearls'!$A$2:$A$2690,A6,'All Pearls'!$H$2:$H$2690,1) -> 13 | C6: =COUNTIF('All Pearls'!$A$2:$A$2690,A6) -> 143 | D6: =COUNTIFS('All Pearls'!$A$2:$A$2690,A6,'All Pearls'!$G$2:$G$2690,1) -> 142 | E6: =C6-D6 -> 1
A7: Forensic Medicine | B7: =COUNTIFS('All Pearls'!$A$2:$A$2690,A7,'All Pearls'!$H$2:$H$2690,1) -> 10 | C7: =COUNTIF('All Pearls'!$A$2:$A$2690,A7) -> 93 | D7: =COUNTIFS('All Pearls'!$A$2:$A$2690,A7,'All Pearls'!$G$2:$G$2690,1) -> 93 | E7: =C7-D7 -> 0
A8: Community Medicine | B8: =COUNTIFS('All Pearls'!$A$2:$A$2690,A8,'All Pearls'!$H$2:$H$2690,1) -> 22 | C8: =COUNTIF('All Pearls'!$A$2:$A$2690,A8) -> 236 | D8: =COUNTIFS('All Pearls'!$A$2:$A$2690,A8,'All Pearls'!$G$2:$G$2690,1) -> 233 | E8: =C8-D8 -> 3
A9: ENT | B9: =COUNTIFS('All Pearls'!$A$2:$A$2690,A9,'All Pearls'!$H$2:$H$2690,1) -> 6 | C9: =COUNTIF('All Pearls'!$A$2:$A$2690,A9) -> 90 | D9: =COUNTIFS('All Pearls'!$A$2:$A$2690,A9,'All Pearls'!$G$2:$G$2690,1) -> 89 | E9: =C9-D9 -> 1
A10: Ophthalmology | B10: =COUNTIFS('All Pearls'!$A$2:$A$2690,A10,'All Pearls'!$H$2:$H$2690,1) -> 12 | C10: =COUNTIF('All Pearls'!$A$2:$A$2690,A10) -> 76 | D10: =COUNTIFS('All Pearls'!$A$2:$A$2690,A10,'All Pearls'!$G$2:$G$2690,1) -> 70 | E10: =C10-D10 -> 6
A11: Medicine | B11: =COUNTIFS('All Pearls'!$A$2:$A$2690,A11,'All Pearls'!$H$2:$H$2690,1) -> 14 | C11: =COUNTIF('All Pearls'!$A$2:$A$2690,A11) -> 365 | D11: =COUNTIFS('All Pearls'!$A$2:$A$2690,A11,'All Pearls'!$G$2:$G$2690,1) -> 359 | E11: =C11-D11 -> 6
A12: Surgery | B12: =COUNTIFS('All Pearls'!$A$2:$A$2690,A12,'All Pearls'!$H$2:$H$2690,1) -> 18 | C12: =COUNTIF('All Pearls'!$A$2:$A$2690,A12) -> 276 | D12: =COUNTIFS('All Pearls'!$A$2:$A$2690,A12,'All Pearls'!$G$2:$G$2690,1) -> 271 | E12: =C12-D12 -> 5
A13: Obstetrics & Gynaecology | B13: =COUNTIFS('All Pearls'!$A$2:$A$2690,A13,'All Pearls'!$H$2:$H$2690,1) -> 11 | C13: =COUNTIF('All Pearls'!$A$2:$A$2690,A13) -> 129 | D13: =COUNTIFS('All Pearls'!$A$2:$A$2690,A13,'All Pearls'!$G$2:$G$2690,1) -> 128 | E13: =C13-D13 -> 1
... A19: Radiology | B19: =COUNTIFS('All Pearls'!$A$2:$A$2690,A19,'All Pearls'!$H$2:$H$2690,1) -> 5 | C19: =COUNTIF('All Pearls'!$A$2:$A$2690,A19) -> 40 | D19: =COUNTIFS('All Pearls'!$A$2:$A$2690,A19,'All Pearls'!$G$2:$G$2690,1) -> 40 | E19: =C19-D19 -> 0
A20: Total | B20: =SUM(B2:B19) -> 222 | C20: =SUM(C2:C19) -> 2689 | D20: =SUM(D2:D19) -> 2618 | E20: =SUM(E2:E19) -> 71
A22: Source: the 18 subject screenshots in this repository, read with OCR and checked by hand at the stitching seams.
A23: "Pearl listings" counts every row; a pearl filed under two subtopics of one subject counts twice there and once in "Unique pearls".
A24: A few titles were cut off at the bottom of a screenshot and completed by hand; those rows carry a note in the All Pearls tab.
A25: Each subject list is complete: no pearls follow the last one shown in its screenshot.

Sheet All Pearls
A1: Subject | B1: Subtopic | C1: Pearl ID | D1: Pearl | E1: Also listed under | F1: Note | G1: First in subject? | H1: First in subtopic?
A2: Anatomy | B2: Embryology | C2: PM2509 | D2: Upper Limb Nerve Injuries | G2: =IF(COUNTIFS($A$2:A2,A2,$C$2:C2,C2)=1,1,0) -> 1 | H2: =IF(COUNTIFS($A$2:A2,A2,$B$2:B2,B2)=1,1,0) -> 1
A3: Anatomy | B3: Embryology | C3: PM2393 | D3: Derivatives of Mesoderm | G3: =IF(COUNTIFS($A$2:A3,A3,$C$2:C3,C3)=1,1,0) -> 1 | H3: =IF(COUNTIFS($A$2:A3,A3,$B$2:B3,B3)=1,1,0) -> 0
A4: Anatomy | B4: Embryology | C4: PM2351 | D4: Embryology of the ear | G4: =IF(COUNTIFS($A$2:A4,A4,$C$2:C4,C4)=1,1,0) -> 1 | H4: =IF(COUNTIFS($A$2:A4,A4,$B$2:B4,B4)=1,1,0) -> 0
A5: Anatomy | B5: Embryology | C5: PM2348 | D5: Homologous structures in male and female genitalia | G5: =IF(COUNTIFS($A$2:A5,A5,$C$2:C5,C5)=1,1,0) -> 1 | H5: =IF(COUNTIFS($A$2:A5,A5,$B$2:B5,B5)=1,1,0) -> 0
A6: Anatomy | B6: Embryology | C6: PM2236 | D6: Twinning | G6: =IF(COUNTIFS($A$2:A6,A6,$C$2:C6,C6)=1,1,0) -> 1 | H6: =IF(COUNTIFS($A$2:A6,A6,$B$2:B6,B6)=1,1,0) -> 0
A7: Anatomy | B7: Embryology | C7: PM2028 | D7: Concepts of Fetal Circulation | G7: =IF(COUNTIFS($A$2:A7,A7,$C$2:C7,C7)=1,1,0) -> 1 | H7: =IF(COUNTIFS($A$2:A7,A7,$B$2:B7,B7)=1,1,0) -> 0
A8: Anatomy | B8: Embryology | C8: PM1979 | D8: Derivatives of Mesonephric (Wolffian) duct and Paramesonephric (Mullerian) duct | G8: =IF(COUNTIFS($A$2:A8,A8,$C$2:C8,C8)=1,1,0) -> 1 | H8: =IF(COUNTIFS($A$2:A8,A8,$B$2:B8,B8)=1,1,0) -> 0
A9: Anatomy | B9: Embryology | C9: PM1974 | D9: Neural crest derivatives | G9: =IF(COUNTIFS($A$2:A9,A9,$C$2:C9,C9)=1,1,0) -> 1 | H9: =IF(COUNTIFS($A$2:A9,A9,$B$2:B9,B9)=1,1,0) -> 0
A10: Anatomy | B10: Embryology | C10: PM1888 | D10: Summary of ocular embryogenesis | G10: =IF(COUNTIFS($A$2:A10,A10,$C$2:C10,C10)=1,1,0) -> 1 | H10: =IF(COUNTIFS($A$2:A10,A10,$B$2:B10,B10)=1,1,0) -> 0
A11: Anatomy | B11: Embryology | C11: PM1239 | D11: Embryological derivatives of the eye | G11: =IF(COUNTIFS($A$2:A11,A11,$C$2:C11,C11)=1,1,0) -> 1 | H11: =IF(COUNTIFS($A$2:A11,A11,$B$2:B11,B11)=1,1,0) -> 0
A12: Anatomy | B12: Embryology | C12: PM1215 | D12: Locations of Congenital Heart Disease | G12: =IF(COUNTIFS($A$2:A12,A12,$C$2:C12,C12)=1,1,0) -> 1 | H12: =IF(COUNTIFS($A$2:A12,A12,$B$2:B12,B12)=1,1,0) -> 0
A13: Anatomy | B13: Embryology | C13: PM1065 | D13: Difference between gastroschisis and omphalocele | G13: =IF(COUNTIFS($A$2:A13,A13,$C$2:C13,C13)=1,1,0) -> 1 | H13: =IF(COUNTIFS($A$2:A13,A13,$B$2:B13,B13)=1,1,0) -> 0
... A25: Anatomy | B25: Embryology | C25: PM0177 | D25: Tissue Stem Cells and their Location | G25: =IF(COUNTIFS($A$2:A25,A25,$C$2:C25,C25)=1,1,0) -> 1 | H25: =IF(COUNTIFS($A$2:A25,A25,$B$2:B25,B25)=1,1,0) -> 0
A26: Anatomy | B26: Histology | C26: PM2250 | D26: Layers of the cerebellar cortex | E26: Neuroanatomy | G26: =IF(COUNTIFS($A$2:A26,A26,$C$2:C26,C26)=1,1,0) -> 1 | H26: =IF(COUNTIFS($A$2:A26,A26,$B$2:B26,B26)=1,1,0) -> 1
A27: Anatomy | B27: Histology | C27: PM2248 | D27: Layers of Cerebral Cortex | E27: Neuroanatomy | G27: =IF(COUNTIFS($A$2:A27,A27,$C$2:C27,C27)=1,1,0) -> 1 | H27: =IF(COUNTIFS($A$2:A27,A27,$B$2:B27,B27)=1,1,0) -> 0
A28: Anatomy | B28: Histology | C28: PM1880 | D28: Cells of the epidermis | G28: =IF(COUNTIFS($A$2:A28,A28,$C$2:C28,C28)=1,1,0) -> 1 | H28: =IF(COUNTIFS($A$2:A28,A28,$B$2:B28,B28)=1,1,0) -> 0
A29: Anatomy | B29: Histology | C29: PM1075 | D29: Various Types of Exocrine Glands with Examples | G29: =IF(COUNTIFS($A$2:A29,A29,$C$2:C29,C29)=1,1,0) -> 1 | H29: =IF(COUNTIFS($A$2:A29,A29,$B$2:B29,B29)=1,1,0) -> 0
A30: Anatomy | B30: Histology | C30: PM1071 | D30: Various Types of Epithelium, Their Location and Functions | G30: =IF(COUNTIFS($A$2:A30,A30,$C$2:C30,C30)=1,1,0) -> 1 | H30: =IF(COUNTIFS($A$2:A30,A30,$B$2:B30,B30)=1,1,0) -> 0
A31: Anatomy | B31: Histology | C31: PM0709 | D31: Comparison between Types of Sweat Glands | G31: =IF(COUNTIFS($A$2:A31,A31,$C$2:C31,C31)=1,1,0) -> 1 | H31: =IF(COUNTIFS($A$2:A31,A31,$B$2:B31,B31)=1,1,0) -> 0
A32: Anatomy | B32: Histology | C32: PM0706 | D32: Microanatomy of Muscle Fibres | G32: =IF(COUNTIFS($A$2:A32,A32,$C$2:C32,C32)=1,1,0) -> 1 | H32: =IF(COUNTIFS($A$2:A32,A32,$B$2:B32,B32)=1,1,0) -> 0
A33: Anatomy | B33: Abdomen and Pelvis | C33: PM2366 | D33: Perineal Body | G33: =IF(COUNTIFS($A$2:A33,A33,$C$2:C33,C33)=1,1,0) -> 1 | H33: =IF(COUNTIFS($A$2:A33,A33,$B$2:B33,B33)=1,1,0) -> 1
A34: Anatomy | B34: Abdomen and Pelvis | C34: PM2282 | D34: Gluteal Muscles | G34: =IF(COUNTIFS($A$2:A34,A34,$C$2:C34,C34)=1,1,0) -> 1 | H34: =IF(COUNTIFS($A$2:A34,A34,$B$2:B34,B34)=1,1,0) -> 0
A35: Anatomy | B35: Abdomen and Pelvis | C35: PM2281 | D35: Sciatic nerve divisions and supply | E35: Lower Limb | G35: =IF(COUNTIFS($A$2:A35,A35,$C$2:C35,C35)=1,1,0) -> 1 | H35: =IF(COUNTIFS($A$2:A35,A35,$B$2:B35,B35)=1,1,0) -> 0
A36: Anatomy | B36: Abdomen and Pelvis | C36: PM2280 | D36: Various muscles of the gluteal region and their innervation | G36: =IF(COUNTIFS($A$2:A36,A36,$C$2:C36,C36)=1,1,0) -> 1 | H36: =IF(COUNTIFS($A$2:A36,A36,$B$2:B36,B36)=1,1,0) -> 0
A37: Anatomy | B37: Abdomen and Pelvis | C37: PM2214 | D37: Lymphatic drainage of pelvic structures | G37: =IF(COUNTIFS($A$2:A37,A37,$C$2:C37,C37)=1,1,0) -> 1 | H37: =IF(COUNTIFS($A$2:A37,A37,$B$2:B37,B37)=1,1,0) -> 0
A38: Anatomy | B38: Abdomen and Pelvis | C38: PM2080 | D38: Calot's triangle and Hepatocystic triangle | G38: =IF(COUNTIFS($A$2:A38,A38,$C$2:C38,C38)=1,1,0) -> 1 | H38: =IF(COUNTIFS($A$2:A38,A38,$B$2:B38,B38)=1,1,0) -> 0
A39: Anatomy | B39: Abdomen and Pelvis | C39: PM2078 | D39: Common sites of porto-systemic anastomosis in portal hypertension | G39: =IF(COUNTIFS($A$2:A39,A39,$C$2:C39,C39)=1,1,0) -> 1 | H39: =IF(COUNTIFS($A$2:A39,A39,$B$2:B39,B39)=1,1,0) -> 0
A40: Anatomy | B40: Abdomen and Pelvis | C40: PM1851 | D40: Fallopian tube | G40: =IF(COUNTIFS($A$2:A40,A40,$C$2:C40,C40)=1,1,0) -> 1 | H40: =IF(COUNTIFS($A$2:A40,A40,$B$2:B40,B40)=1,1,0) -> 0
A41: Anatomy | B41: Abdomen and Pelvis | C41: PM1580 | D41: Characteristic differentiating features of the jejunum and ileum | G41: =IF(COUNTIFS($A$2:A41,A41,$C$2:C41,C41)=1,1,0) -> 1 | H41: =IF(COUNTIFS($A$2:A41,A41,$B$2:B41,B41)=1,1,0) -> 0
A42: Anatomy | B42: Abdomen and Pelvis | C42: PM1371 | D42: Passaro’s Triangle | G42: =IF(COUNTIFS($A$2:A42,A42,$C$2:C42,C42)=1,1,0) -> 1 | H42: =IF(COUNTIFS($A$2:A42,A42,$B$2:B42,B42)=1,1,0) -> 0
A43: Anatomy | B43: Abdomen and Pelvis | C43: PM1352 | D43: Nerve supply in the pelvis | G43: =IF(COUNTIFS($A$2:A43,A43,$C$2:C43,C43)=1,1,0) -> 1 | H43: =IF(COUNTIFS($A$2:A43,A43,$B$2:B43,B43)=1,1,0) -> 0
A44: Anatomy | B44: Abdomen and Pelvis | C44: PM1351 | D44: Contents of the Broad ligament | G44: =IF(COUNTIFS($A$2:A44,A44,$C$2:C44,C44)=1,1,0) -> 1 | H44: =IF(COUNTIFS($A$2:A44,A44,$B$2:B44,B44)=1,1,0) -> 0
A45: Anatomy | B45: Abdomen and Pelvis | C45: PM1292 | D45: Length of various structures in the human body | G45: =IF(COUNTIFS($A$2:A45,A45,$C$2:C45,C45)=1,1,0) -> 1 | H45: =IF(COUNTIFS($A$2:A45,A45,$B$2:B45,B45)=1,1,0) -> 0
A46: Anatomy | B46: Abdomen and Pelvis | C46: PM1265 | D46: Features of anal canal above and below pectinate line | G46: =IF(COUNTIFS($A$2:A46,A46,$C$2:C46,C46)=1,1,0) -> 1 | H46: =IF(COUNTIFS($A$2:A46,A46,$B$2:B46,B46)=1,1,0) -> 0
A47: Anatomy | B47: Abdomen and Pelvis | C47: PM1237 | D47: Sacral Plexus | G47: =IF(COUNTIFS($A$2:A47,A47,$C$2:C47,C47)=1,1,0) -> 1 | H47: =IF(COUNTIFS($A$2:A47,A47,$B$2:B47,B47)=1,1,0) -> 0
... A110: Anatomy | B110: Neuroanatomy | C110: PM2251 | D110: Neurons and fibers of the cerebellum | G110: =IF(COUNTIFS($A$2:A110,A110,$C$2:C110,C110)=1,1,0) -> 1 | H110: =IF(COUNTIFS($A$2:A110,A110,$B$2:B110,B110)=1,1,0) -> 0
A111: Anatomy | B111: Neuroanatomy | C111: PM2250 | D111: Layers of the cerebellar cortex | E111: Histology | G111: =IF(COUNTIFS($A$2:A111,A111,$C$2:C111,C111)=1,1,0) -> 0 | H111: =IF(COUNTIFS($A$2:A111,A111,$B$2:B111,B111)=1,1,0) -> 0
A112: Anatomy | B112: Neuroanatomy | C112: PM2248 | D112: Layers of Cerebral Cortex | E112: Histology | G112: =IF(COUNTIFS($A$2:A112,A112,$C$2:C112,C112)=1,1,0) -> 0 | H112: =IF(COUNTIFS($A$2:A112,A112,$B$2:B112,B112)=1,1,0) -> 0
A113: Anatomy | B113: Neuroanatomy | C113: PM2247 | D113: Internal capsule parts and fibers | G113: =IF(COUNTIFS($A$2:A113,A113,$C$2:C113,C113)=1,1,0) -> 1 | H113: =IF(COUNTIFS($A$2:A113,A113,$B$2:B113,B113)=1,1,0) -> 0
...

Sheet Anatomy
A1: Subtopic | B1: Pearl ID | C1: Pearl | D1: Also listed under | E1: Note
A2: Embryology | B2: PM2509 | C2: Upper Limb Nerve Injuries
A3: Embryology | B3: PM2393 | C3: Derivatives of Mesoderm
A4: Embryology | B4: PM2351 | C4: Embryology of the ear
A5: Embryology | B5: PM2348 | C5: Homologous structures in male and female genitalia
A6: Embryology | B6: PM2236 | C6: Twinning
A7: Embryology | B7: PM2028 | C7: Concepts of Fetal Circulation
A8: Embryology | B8: PM1979 | C8: Derivatives of Mesonephric (Wolffian) duct and Paramesonephric (Mullerian) duct
A9: Embryology | B9: PM1974 | C9: Neural crest derivatives
A10: Embryology | B10: PM1888 | C10: Summary of ocular embryogenesis
A11: Embryology | B11: PM1239 | C11: Embryological derivatives of the eye
A12: Embryology | B12: PM1215 | C12: Locations of Congenital Heart Disease
A13: Embryology | B13: PM1065 | C13: Difference between gastroschisis and omphalocele
... A25: Embryology | B25: PM0177 | C25: Tissue Stem Cells and their Location
A26: Histology | B26: PM2250 | C26: Layers of the cerebellar cortex | D26: Neuroanatomy
A27: Histology | B27: PM2248 | C27: Layers of Cerebral Cortex | D27: Neuroanatomy
A28: Histology | B28: PM1880 | C28: Cells of the epidermis
A29: Histology | B29: PM1075 | C29: Various Types of Exocrine Glands with Examples
A30: Histology | B30: PM1071 | C30: Various Types of Epithelium, Their Location and Functions
A31: Histology | B31: PM0709 | C31: Comparison between Types of Sweat Glands
A32: Histology | B32: PM0706 | C32: Microanatomy of Muscle Fibres
A33: Abdomen and Pelvis | B33: PM2366 | C33: Perineal Body
A34: Abdomen and Pelvis | B34: PM2282 | C34: Gluteal Muscles
A35: Abdomen and Pelvis | B35: PM2281 | C35: Sciatic nerve divisions and supply | D35: Lower Limb
A36: Abdomen and Pelvis | B36: PM2280 | C36: Various muscles of the gluteal region and their innervation
A37: Abdomen and Pelvis | B37: PM2214 | C37: Lymphatic drainage of pelvic structures
A38: Abdomen and Pelvis | B38: PM2080 | C38: Calot's triangle and Hepatocystic triangle
A39: Abdomen and Pelvis | B39: PM2078 | C39: Common sites of porto-systemic anastomosis in portal hypertension
A40: Abdomen and Pelvis | B40: PM1851 | C40: Fallopian tube
A41: Abdomen and Pelvis | B41: PM1580 | C41: Characteristic differentiating features of the jejunum and ileum
A42: Abdomen and Pelvis | B42: PM1371 | C42: Passaro’s Triangle
A43: Abdomen and Pelvis | B43: PM1352 | C43: Nerve supply in the pelvis
A44: Abdomen and Pelvis | B44: PM1351 | C44: Contents of the Broad ligament
A45: Abdomen and Pelvis | B45: PM1292 | C45: Length of various structures in the human body
A46: Abdomen and Pelvis | B46: PM1265 | C46: Features of anal canal above and below pectinate line
A47: Abdomen and Pelvis | B47: PM1237 | C47: Sacral Plexus
... A110: Neuroanatomy | B110: PM2251 | C110: Neurons and fibers of the cerebellum
A111: Neuroanatomy | B111: PM2250 | C111: Layers of the cerebellar cortex | D111: Histology
A112: Neuroanatomy | B112: PM2248 | C112: Layers of Cerebral Cortex | D112: Histology
A113: Neuroanatomy | B113: PM2247 | C113: Internal capsule parts and fibers
...

Sheet Physiology
A1: Subtopic | B1: Pearl ID | C1: Pearl | D1: Also listed under | E1: Note
A2: General Physiology | B2: PM2358 | C2: Na+ - K+ ATPase pump
A3: General Physiology | B3: PM2317 | C3: Membrane receptors and their mechanisms
A4: General Physiology | B4: PM1972 | C4: Resting membrane potential (RMP) in tissues
A5: General Physiology | B5: PM1957 | C5: Extracellular fluid vs Intracellular fluid
A6: General Physiology | B6: PM1906 | C6: Graded potential vs Action potential
A7: General Physiology | B7: PM1905 | C7: Absolute and relative refractory period
A8: General Physiology | B8: PM1895 | C8: Sensory Receptors
A9: General Physiology | B9: PM1497 | C9: Glucose Transporters
A10: General Physiology | B10: PM1340 | C10: Factors affecting K+ distribution between ECF and ICF concentration
A11: General Physiology | B11: PM0730 | C11: Transient Receptor Potential (TRP) Ion Channels/Receptors
A12: General Physiology | B12: PM0463 | C12: Distribution of body fluids
A13: General Physiology | B13: PM0462 | C13: Daily fluid intake and output
... A68: Central Nervous System | B68: PM1323 | C68: Neurotransmitters and Hormones that influence Feeding and Satiety Centers in the Hypothalamus
A69: Central Nervous System | B69: PM0998 | C69: Effects of Various Lesions and Brainstem Transections | D69: The Respiratory System
A70: Central Nervous System | B70: PM0997 | C70: Respiratory Centres | D70: The Respiratory System
A71: Central Nervous System | B71: PM0922 | C71: Functions of hypothalamus
A72: Central Nervous System | B72: PM0921 | C72: Reward and punishment centers in brain
A73: Central Nervous System | B73: PM0920 | C73: Components of limbic system
A74: Central Nervous System | B74: PM0919 | C74: Divisions of thalamic nuclei
A75: Central Nervous System | B75: PM0918 | C75: Divisions of thalamus
A76: Central Nervous System | B76: PM0917 | C76: Functions of principal afferent systems to cerebellum
A77: Central Nervous System | B77: PM0915 | C77: Functional divisions of the cerebellum
A78: Central Nervous System | B78: PM0907 | C78: Forms of Memory
A79: Central Nervous System | B79: PM0905 | C79: Difference between NREM and REM Sleep
A80: Central Nervous System | B80: PM0904 | C80: Neurochemical changes in Sleep-Wake Cycle
A81: Central Nervous System | B81: PM0903 | C81: Distribution of Sleep Stages in Young Adults
A82: Central Nervous System | B82: PM0902 | C82: Stages of Arousal and Sleep
... A112: The Respiratory System | B112: PM1001 | C112: Respiratory responses to exercise
A113: The Respiratory System | B113: PM0998 | C113: Effects of Various Lesions and Brainstem Transections | D113: Central Nervous System
A114: The Respiratory System | B114: PM0997 | C114: Respiratory Centres | D114: Central Nervous System
A115: The Respiratory System | B115: PM0996 | C115: Factors affecting 2,3 -DPG
A116: The Respiratory System | B116: PM0983 | C116: Structure of Airways
A117: The Respiratory System | B117: PM0113 | C117: Zones of Pulmonary Blood Flow
A118: The Respiratory System | B118: PM0105 | C118: Physiological significance of Hering-Breuer inflation and deflation reflex
A119: The Respiratory System | B119: PM0104 | C119: Respiratory responses mediated by airway and lung receptors
A120: The Respiratory System | B120: PM0103 | C120: Side effect of opioids on Respiration
A121: The Respiratory System | B121: PM0096 | C121: Oxygen myoglobin dissociation curve
A122: The Respiratory System | B122: PM0095 | C122: P50
A123: The Respiratory System | B123: PM0090 | C123: Hyaline membrane disease
...

Sheet Biochemistry
A1: Subtopic | B1: Pearl ID | C1: Pearl | D1: Also listed under | E1: Note
A2: General Topics- Videos | B2: PM0909 | C2: Factors Affecting the Rate of Reaction
A3: Carbohydrates | B3: PM2311 | C3: Pyruvate metabolism
A4: Carbohydrates | B4: PM2309 | C4: Transport of ammonia in blood (Cahill and Cori cycle)
A5: Carbohydrates | B5: PM2194 | C5: Essential Pentosuria
A6: Carbohydrates | B6: PM2054 | C6: Irreversible enzymes in gluconeogenesis pathway
A7: Carbohydrates | B7: PM0982 | C7: Phases of HMP Shunt and the Enzymes Involved
A8: Carbohydrates | B8: PM0964 | C8: Glycogen Storage Diseases
A9: Carbohydrates | B9: PM0963 | C9: Glycogenolysis
A10: Carbohydrates | B10: PM0962 | C10: Steps in Glycogenesis & Respective Enzymes
A11: Carbohydrates | B11: PM0961 | C11: Structural Bond of Various Polysaccharides
A12: Carbohydrates | B12: PM0944 | C12: Test for Carbohydrates
A13: Carbohydrates | B13: PM0943 | C13: Method of Glucose Estimation
... A16: Carbohydrates | B16: PM0936 | C16: Aldoses and Ketoses
A17: Carbohydrates | B17: PM0856 | C17: Lysosomal storage diseases | D17: Lipids
A18: Carbohydrates | B18: PM0816 | C18: Diseases due to glycoprotein defect
A19: Carbohydrates | B19: PM0808 | C19: Some Important Methods Used to Study Glycoproteins
A20: Carbohydrates | B20: PM0807 | C20: Glycoprotein and their functions
A21: Carbohydrates | B21: PM0525 | C21: Reducing Equivalents and Their Uses | D21: Lipids
A22: Carbohydrates | B22: PM0091 | C22: Steps involved in TCA cycle
A23: Carbohydrates | B23: PM0081 | C23: Biologically important Glycosoaminoglycans(GAG's)
A24: Carbohydrates | B24: PM0080 | C24: Energy production in TCA Cycle | D24: Bioenergetics
A25: Carbohydrates | B25: PM0079 | C25: Inhibitors of metabolic pathways
A26: Carbohydrates | B26: PM0078 | C26: Electron transport chain: components and its inhibitors | D26: Bioenergetics
A27: Carbohydrates | B27: PM0030 | C27: Sites of various pathways in cell | D27: Amino acids and proteins; Lipids
A28: Carbohydrates | B28: PM0002 | C28: Glucose transporters and their locations
A29: Amino acids and proteins | B29: PM2322 | C29: Carcinoid syndrome
A30: Amino acids and proteins | B30: PM2310 | C30: Maple syrup urine disease(MSUD)
A31: Amino acids and proteins | B31: PM2307 | C31: Menkes disease | D31: Genetics
A32: Amino acids and proteins | B32: PM2306 | C32: Synthesis of collagen and its disorders
A33: Amino acids and proteins | B33: PM2305 | C33: Phenylketonuria
A34: Amino acids and proteins | B34: PM2304 | C34: Homocystinuria
A35: Amino acids and proteins | B35: PM2196 | C35: Amino Acid Derivatives
A36: Amino acids and proteins | B36: PM1791 | C36: Types of Chromatography
A37: Amino acids and proteins | B37: PM1402 | C37: Types of flavoprotein
A38: Amino acids and proteins | B38: PM1401 | C38: Structure of proteins
A39: Amino acids and proteins | B39: PM0627 | C39: Inborn Errors of Amino Acid Metabolism and Their Associated Urine Odor
A40: Amino acids and proteins | B40: PM0625 | C40: Amino acid Enzymatic Disorders and the Associated Enzymes
A41: Amino acids and proteins | B41: PM0590 | C41: Types of tyrosinemia with deficient enzymes
A42: Amino acids and proteins | B42: PM0579 | C42: Amino Acids and their Biological Amines
...

Sheet Pathology
A1: Subtopic | B1: Pearl ID | C1: Pearl | D1: Also listed under | E1: Note
A2: General Pathology | B2: PM2412 | C2: Types of Hypersensitivity
A3: General Pathology | B3: PM2357 | C3: Types of calcifications
A4: General Pathology | B4: PM2356 | C4: Intracellular accumulations
A5: General Pathology | B5: PM2355 | C5: Types of granulomas
A6: General Pathology | B6: PM2353 | C6: Types of giant cells
A7: General Pathology | B7: PM2352 | C7: Chronic granulomatous disease
A8: General Pathology | B8: PM2265 | C8: Onion Skin Appearance in Pathology
A9: General Pathology | B9: PM2227 | C9: Necrosis vs Apoptosis
A10: General Pathology | B10: PM2206 | C10: Various stains and their applications in Pathology and Microbiology
A11: General Pathology | B11: PM2173 | C11: Pattern of nuclear body suggests the type of antibody present in patient’s serum.
A12: General Pathology | B12: PM2137 | C12: Transplant Rejection and Hypersensitivity
A13: General Pathology | B13: PM2112 | C13: Tumor suppressor genes
... A88: Hemolytic Anemias & RBC Disorders | B88: PM1468 | C88: WHO Polycythemia Vera Criteria
A89: Hemolytic Anemias & RBC Disorders | B89: PM1285 | C89: Morphological Classification of Anemias | D89: Hematology
A90: Hemolytic Anemias & RBC Disorders | B90: PM0027 | C90: Autoimmune Hemolytic Anemia
A91: Hematology | B91: PM2430 | C91: FAB classification of ALL
A92: Hematology | B92: PM2429 | C92: Causes of Thrombocytopenia
A93: Hematology | B93: PM2423 | C93: Burkitt's Lymphoma
A94: Hematology | B94: PM2420 | C94: Causes of Iron Deficiency Anemia
A95: Hematology | B95: PM2419 | C95: Factors affecting iron absorption
A96: Hematology | B96: PM2146 | C96: Differential Diagnosis of Microcytic Anaemia
A97: Hematology | B97: PM2064 | C97: Thalassemia syndromes
A98: Hematology | B98: PM1998 | C98: Important Translocations in AML
A99: Hematology | B99: PM1965 | C99: International Staging System (ISS) for multiple myeloma:
A100: Hematology | B100: PM1951 | C100: Platelet disorders
A101: Hematology | B101: PM1949 | C101: Differences between Bleeding Disorders and Coagulation disorders
... A117: Hematology | B117: PM1440 | C117: Causes of Megaloblastic Anemia
A118: Hematology | B118: PM1285 | C118: Morphological Classification of Anemias | D118: Hemolytic Anemias & RBC Disorders
A119: Hematology | B119: PM1273 | C119: Classification of acquired Immune Hemolytic Anemias
A120: Hematology | B120: PM1268 | C120: Features of Peripheral Blood Smear in Different Anemias
A121: Hematology | B121: PM1247 | C121: Classification of Hemolytic Anemias
A122: Hematology | B122: PM1244 | C122: WHO classification of Acute Myeloid Leukemia (AML)
A123: Hematology | B123: PM1235 | C123: Cytogenetic Translocation and Associated Oncogenes Often Seen in Lymphoid Malignancies
A124: Hematology | B124: PM1207 | C124: Prognostic Factors in Acute Myeloid Leukemia (AML)
A125: Hematology | B125: PM1193 | C125: Cytochemistry of Acute Leukemias
A126: Hematology | B126: PM1190 | C126: Immunophenotyping of Acute Lymphocytic Leukemia (ALL)
A127: Hematology | B127: PM1188 | C127: Panel of monoclonal antibodies for classification of leukemias
A128: Hematology | B128: PM1187 | C128: FAB classification
A129: Hematology | B129: PM1179 | C129: Morphological Characteristics of Blasts Cells in Acute Lymphoblastic Leukemia vs. Acute Myeloid Leukemia
...

Sheet Pharmacology
A1: Subtopic | B1: Pearl ID | C1: Pearl | D1: Also listed under | E1: Note
A2: General Pharmacology | B2: PM2414 | C2: Drugs causing QT prolongation and torsades de pointes
A3: General Pharmacology | B3: PM2379 | C3: Drug regulatory schedules 1940: (2016 update)
A4: General Pharmacology | B4: PM2378 | C4: Zero order vs First order kinetics of drugs
A5: General Pharmacology | B5: PM2369 | C5: Drugs metabolised by glucuronidation
A6: General Pharmacology | B6: PM2368 | C6: Metabolism of drugs
A7: General Pharmacology | B7: PM2367 | C7: Dialyzable and non-dialyzable drugs
A8: General Pharmacology | B8: PM2365 | C8: Drugs which need Therapeutic Drug Monitoring (TDM)
A9: General Pharmacology | B9: PM2364 | C9: Drugs having high first pass metabolism
A10: General Pharmacology | B10: PM2363 | C10: Drugs showing increased absorption in presence of food
A11: General Pharmacology | B11: PM2022 | C11: Teratogenic drugs and the birth defects
A12: General Pharmacology | B12: PM1735 | C12: Difference between microsomal and non microsomal enzymes:
A13: General Pharmacology | B13: PM1734 | C13: Phases of drug metabolism
... A113: Endocrine System | B113: PM0679 | C113: Drug of choice for hyperthyroidism/thyrotoxicosis in pregnancy
A114: Endocrine System | B114: PM0553 | C114: PDE inhibitors | D114: Respiratory System
A115: Endocrine System | B115: PM0371 | C115: Mechanisms of Action of Hormones
A116: Endocrine System | B116: PM0370 | C116: Classification of Hormones According to their Chemical Structure
A117: Autacoids | B117: PM2335 | C117: Important drugs for rheumatoid arthritis
A118: Autacoids | B118: PM1929 | C118: Drugs precipitating Gout
A119: Autacoids | B119: PM0765 | C119: Difference in COX-1 and COX-2
A120: Autacoids | B120: PM0642 | C120: Acid resistant penicillins: mnemonic "VODKA"
A121: Autacoids | B121: PM0605 | C121: Factor Xa: IIa inhibition activity of antithrombin activators
A122: Autacoids | B122: PM0580 | C122: Triptans - 5HT 1B/1D agonists
A123: Autacoids | B123: PM0523 | C123: Some Important Points about Selective COX-2 Inhibitors
A124: Autacoids | B124: PM0522 | C124: Preferential COX-2 inhibitors: mnemonic "NAMED"
A125: Autacoids | B125: PM0521 | C125: Prostaglandins effect on platelet action
A126: Hematology | B126: PM2398 | C126: Classification of anti-platelet drugs
... A131: Hematology | B131: PM0603 | C131: Plasminogen activators (classification of fibrinolytics)
A132: Respiratory System | B132: PM0553 | C132: PDE inhibitors | D132: Endocrine System
A133: Gastrointestinal Drugs | B133: PM2457 | C133: Drugs used in irritable bowel syndrome (IBS)
A134: Anti-Neoplastic Agents | B134: PM1565 | C134: Uses of methotrexate (mnemonic: CANCER)
A135: Anti-Neoplastic Agents | B135: PM1517 | C135: Unique adverse effect profile of Zidovudine
A136: Anti-Neoplastic Agents | B136: PM1353 | C136: Classification of antineoplastic drugs
A137: Anti-Neoplastic Agents | B137: PM1082 | C137: Monoclonal antibodies nomenclature
A138: Anti-Neoplastic Agents | B138: PM1081 | C138: Indications for Imatinib
A139: Anti-Neoplastic Agents | B139: PM0925 | C139: Microtubule stabilising vs polymerisation inhibiting agents
A140: Anti-Neoplastic Agents | B140: PM0914 | C140: Cell cycle specific and non-specific cytotoxic agents
A141: Anti-Neoplastic Agents | B141: PM0910 | C141: Topoisomerase Inhibitors
A142: Newer Drugs | B142: PM2405 | C142: FDA approved drugs in 2019
A143: Newer Drugs | B143: PM1787 | C143: FDA approved drugs in 2017
...

Sheet Forensic Medicine
A1: Subtopic | B1: Pearl ID | C1: Pearl | D1: Also listed under | E1: Note
A2: Identification | B2: PM0060 | C2: Estimation of stature using skeletal remains
A3: Identification | B3: PM0059 | C3: Medico-legal importance of age
A4: Identification | B4: PM0058 | C4: Ossification centres appearing before birth
A5: Identification | B5: PM0057 | C5: Appearance of ossification centres of carpal bones
A6: Identification | B6: PM0056 | C6: Fusion of skull sutures and closure of fontanelles
A7: Identification | B7: PM0055 | C7: Permanent dentition
A8: Identification | B8: PM0054 | C8: Temporary dentition
A9: Identification | B9: PM0053 | C9: Indices for determination of race and sex of an individual
A10: Identification | B10: PM0050 | C10: Cephalic index
A11: Medical Jurisprudence | B11: PM2391 | C11: Contributory negligence
A12: Medical Jurisprudence | B12: PM2131 | C12: Medical Termination of Pregnancy Act - MTP Act 1971
A13: Medical Jurisprudence | B13: PM2059 | C13: BNS section 22, M'Naghten's rule
... A94: Others | B94: PM0861 | C94: Post-mortem Staining in Poisonings

Sheet Community Medicine
A1: Subtopic | B1: Pearl ID | C1: Pearl | D1: Also listed under | E1: Note
A2: Preventive medicine - Marrow Edition 3 (2019) | B2: PM2211 | C2: Vaccines and their Strains
A3: Concepts of Health and Disease | B3: PM2224 | C3: Health Data
A4: Concepts of Health and Disease | B4: PM2044 | C4: Crude death rate
A5: Concepts of Health and Disease | B5: PM1700 | C5: Neonatal Mortality Rate
A6: Concepts of Health and Disease | B6: PM1699 | C6: Perinatal Mortality Rate
A7: Concepts of Health and Disease | B7: PM1698 | C7: Maternal Mortality Ratio
A8: Concepts of Health and Disease | B8: PM0138 | C8: Socio-Economic Indicators of Health
A9: Concepts of Health and Disease | B9: PM0137 | C9: Disability Adjusted Life Year (DALY)
A10: Concepts of Health and Disease | B10: PM0136 | C10: QALY vs. DALY
A11: Concepts of Health and Disease | B11: PM0134 | C11: HDI vs. PQLI
A12: Epidemiology | B12: PM1691 | C12: National Immunization Schedule (India)
A13: Epidemiology | B13: PM0814 | C13: Methods of Sterilization and Disinfection
... A62: Epidemiology of Communicable Diseases | B62: PM1775 | C62: Recommendations - WHO Guidelines for preventive chemotherapy to control soil-transmitted helminth infections in at-risk population groups
A63: Epidemiology of Communicable Diseases | B63: PM1731 | C63: Arthropod-borne diseases | D63: Environment and Health
A64: Epidemiology of Communicable Diseases | B64: PM1726 | C64: Flea Indices
A65: Epidemiology of Communicable Diseases | B65: PM1725 | C65: Rabies vaccines and immunoglobulins schedules
A66: Epidemiology of Communicable Diseases | B66: PM1724 | C66: Classification of Zoonoses
A67: Epidemiology of Communicable Diseases | B67: PM1720 | C67: ATT Regimen for TB Patients
A68: Epidemiology of Communicable Diseases | B68: PM1719 | C68: Classification of TB Patients Based on History of Treatment
A69: Epidemiology of Communicable Diseases | B69: PM1718 | C69: Diagnostic algorithm for Pulmonary TB — National Tuberculosis Elimination Programme (NTEP) 2020 Guidelines
A70: Epidemiology of Communicable Diseases | B70: PM1713 | C70: Ridley's logarithmic scale in determining Bacterial Index
A71: Epidemiology of Communicable Diseases | B71: PM1710 | C71: Important sexually transmitted pathogens and the diseases caused by them
A72: Epidemiology of Communicable Diseases | B72: PM1696 | C72: Treatment of Malaria
A73: Epidemiology of Communicable Diseases | B73: PM0594 | C73: 2021 NACO Guidelines on Post-exposure Prophylaxis (PEP) for HIV
A74: Epidemiology of Communicable Diseases | B74: PM0495 | C74: Biological Transmission in Vector-Borne Diseases
A75: Epidemiology of Communicable Diseases | B75: PM0491 | C75: Modes of Transmission of Communicable Diseases
... A131: Environment and Health | B131: PM2390 | C131: Comparison between mosquito-borne and transfusion-transmitted malaria.
A132: Environment and Health | B132: PM1731 | C132: Arthropod-borne diseases | D132: Epidemiology of Communicable Diseases
A133: Environment and Health | B133: PM1686 | C133: Insecticides
A134: Environment and Health | B134: PM1684 | C134: Ticks
A135: Environment and Health | B135: PM1683 | C135: Rat Fleas
A136: Environment and Health | B136: PM1681 | C136: Lice
A137: Environment and Health | B137: PM1676 | C137: Sandfly
A138: Environment and Health | B138: PM1669 | C138: Mosquito Control Measures
A139: Environment and Health | B139: PM1668 | C139: The Mosquito
A140: Environment and Health | B140: PM1666 | C140: Oxidation Ponds
A141: Environment and Health | B141: PM1664 | C141: Modern Sewage Treatment
A142: Environment and Health | B142: PM1662 | C142: Strength of Sewage
A143: Environment and Health | B143: PM1661 | C143: Septic Tank
...

Sheet ENT
A1: Subtopic | B1: Pearl ID | C1: Pearl | D1: Also listed under | E1: Note
A2: Ear | B2: PM2512 | C2: Stapedotomy special considerations and complications
A3: Ear | B3: PM2351 | C3: Embryology of the ear
A4: Ear | B4: PM2222 | C4: Myringotomy
A5: Ear | B5: PM2205 | C5: Eagle syndrome
A6: Ear | B6: PM1819 | C6: Auditory Brainstem Implant
A7: Ear | B7: PM1818 | C7: BAHA (Bone Anchored Hearing Aid)
A8: Ear | B8: PM1817 | C8: Cochlear implant
A9: Ear | B9: PM1807 | C9: Inner Ear Abnormalities
A10: Ear | B10: PM1800 | C10: Tuning fork tests
A11: Ear | B11: PM1755 | C11: BERA (Brainstem Evoked Response Audiometry) or ABR (Auditory Brainstem Response)
A12: Ear | B12: PM1754 | C12: OAEs - Otoacoustic emissions
A13: Ear | B13: PM1753 | C13: Speech audiometry
... A76: Pharynx | B76: PM1294 | C76: Parts of Pharynx
A77: Pharynx | B77: PM1097 | C77: Lymph Node Levels in the Neck | D77: Throat
A78: Larynx | B78: PM2513 | C78: TNM classification of glottic carcinoma
A79: Larynx | B79: PM1978 | C79: Muscles of larynx
A80: Larynx | B80: PM1801 | C80: Child vs Adult airway
A81: Larynx | B81: PM1096 | C81: Sites and subsites of the larynx (AJCC Classification)
A82: Larynx | B82: PM1094 | C82: Various Vocal Cord Palsies
A83: Larynx | B83: PM1093 | C83: Positions of the Vocal Cord
A84: Larynx | B84: PM1091 | C84: Nerves of Larynx
A85: Larynx | B85: PM0931 | C85: Differences between adult and infant Larynx
A86: Larynx | B86: PM0930 | C86: Development of Larynx
A87: Larynx | B87: PM0927 | C87: Cartilages of Larynx
A88: Larynx | B88: PM0403 | C88: Precautions during laser airway surgery
A89: Instruments | B89: PM1298 | C89: Laser Application in ENT
A90: Throat | B90: PM2157 | C90: Types of Tracheostomy
A91: Throat | B91: PM1097 | C91: Lymph Node Levels in the Neck | D91: Pharynx

Sheet Ophthalmology
A1: Subtopic | B1: Pearl ID | C1: Pearl | D1: Also listed under | E1: Note
A2: Basics of Ophthalmology | B2: PM2228 | C2: Superior orbital fissure
A3: Basics of Ophthalmology | B3: PM1888 | C3: Summary of ocular embryogenesis
A4: Basics of Ophthalmology | B4: PM1887 | C4: Visual development
A5: Basics of Ophthalmology | B5: PM1240 | C5: Extraocular Muscles and Their Actions
A6: Basics of Ophthalmology | B6: PM1239 | C6: Embryological derivatives of the eye
A7: Basics of Ophthalmology | B7: PM1084 | C7: Sympathetic and parasympathetic nerve supply to iris muscles
A8: Basics of Ophthalmology | B8: PM1014 | C8: Grades of binocular vision
A9: Basics of Ophthalmology | B9: PM1013 | C9: Laws governing ocular movements
A10: Basics of Ophthalmology | B10: PM0843 | C10: Axes of the Eye
A11: Basics of Ophthalmology | B11: PM0833 | C11: Differences between Rods and Cones
A12: Basics of Ophthalmology | B12: PM0800 | C12: Layers of the Tear Film | D12: Conjunctiva
A13: Basics of Ophthalmology | B13: PM0790 | C13: Causes of small and dilated pupils
A14: Basics of Ophthalmology | B14: PM0789 | C14: Order of neurons in the visual pathway
A15: Basics of Ophthalmology | B15: PM0406 | C15: Oculocardiac Reflex
A16: Errors in Optics | B16: PM0723 | C16: Surgical treatment of hypermetropia | D16: Cornea
A17: Errors in Optics | B17: PM0722 | C17: Grading of Hypermetropia
A18: Errors in Optics | B18: PM0721 | C18: Surgical correction of Myopia | D18: Cornea
A19: Errors in Optics | B19: PM0717 | C19: Grading of Myopia
A20: Errors in Optics | B20: PM0716 | C20: Causes of Myopia
A21: Errors in Optics | B21: PM0345 | C21: Types of contact lens (based on the material)
A22: Conjunctiva | B22: PM0801 | C22: Tear film tests used for the diagnosis of dry eye
A23: Conjunctiva | B23: PM0800 | C23: Layers of the Tear Film | D23: Basics of Ophthalmology
A24: Conjunctiva | B24: PM0799 | C24: Surgical treatment of different types of ptosis
A25: Conjunctiva | B25: PM0798 | C25: Surgical Modalities Used in Correcting Ectropion
A26: Conjunctiva | B26: PM0075 | C26: Trachoma Staging
A27: Cornea | B27: PM1919 | C27: Stromal Dystrophies and Staining
A28: Cornea | B28: PM1918 | C28: Causes of congenital opacities of the cornea
A29: Cornea | B29: PM1908 | C29: Important investigations related to the cornea
A30: Cornea | B30: PM1907 | C30: Clinical differential diagnosis of corneal ulcer
A31: Cornea | B31: PM1723 | C31: Different types of keratic precipitates (KPs) | D31: Specific Disorders of the Eye
A32: Cornea | B32: PM0783 | C32: Vogt's striae
A33: Cornea | B33: PM0755 | C33: Corneal Preservation
A34: Cornea | B34: PM0754 | C34: Corneal Opacities
A35: Cornea | B35: PM0723 | C35: Surgical treatment of hypermetropia | D35: Errors in Optics
A36: Cornea | B36: PM0721 | C36: Surgical correction of Myopia | D36: Errors in Optics
A37: Cornea | B37: PM0711 | C37: Types of Corneal Dystrophies
A38: Cornea | B38: PM0710 | C38: Ocular lesions of Herpes Simplex
A39: Retina and Vitreous | B39: PM2487 | C39: Early treatment diabetic retinopathy study (ETDRS) classification
A40: Retina and Vitreous | B40: PM2486 | C40: Hypertensive retinopathy
...

Sheet Medicine
A1: Subtopic | B1: Pearl ID | C1: Pearl | D1: Also listed under | E1: Note
A2: General | B2: PM2180 | C2: Hypervitaminosis A
A3: General | B3: PM2065 | C3: Body mass index
A4: General | B4: PM2055 | C4: Inheritance pattern of important diseases
A5: General | B5: PM2040 | C5: Conditions commonly associated with Klippel-Feil syndrome
A6: General | B6: PM1338 | C6: Principal buffers in the body
A7: General | B7: PM1233 | C7: Indications of Plasma exchange Therapy
A8: General | B8: PM0276 | C8: Pathological Conditions and Associated Neoplasms
A9: General | B9: PM0272 | C9: Paraneoplastic Syndromes and Underlying Cancers
A10: General | B10: PM0188 | C10: Adult cardiac arrest algorithm (Updated as per 2025 guidelines)
A11: General | B11: PM0180 | C11: Nail findings and associated systemic conditions
A12: General | B12: PM0133 | C12: Important dates and events
A13: Endocrine System | B13: PM2410 | C13: Classification of Anti- Thyroid Drugs
... A136: Respiratory System | B136: PM2190 | C136: Empirical Antibiotic Treatment of Community-Acquired Pneumonia (CAP)
A137: Respiratory System | B137: PM1977 | C137: Causes of CorPulmonale | D137: Cardiovascular System
A138: Respiratory System | B138: PM1879 | C138: Types of pleural effusion
A139: Respiratory System | B139: PM1863 | C139: Types of Respiratory Failure
A140: Respiratory System | B140: PM1845 | C140: Incidence of lung cancer according to histology
A141: Respiratory System | B141: PM1843 | C141: Lobes involved in various lung diseases
A142: Respiratory System | B142: PM1840 | C142: Extrinsic vs Intrinsic asthma
A143: Respiratory System | B143: PM1821 | C143: Evaluation of solitary pulmonary nodule
A144: Respiratory System | B144: PM1718 | C144: Diagnostic algorithm for Pulmonary TB — National Tuberculosis Elimination Programme (NTEP) 2020 Guidelines | D144: Infectious Diseases
A145: Respiratory System | B145: PM1555 | C145: Disorders Caused by Immediate Hypersensitivity
A146: Respiratory System | B146: PM1172 | C146: PFT for obstructive vs restrictive diseases
A147: Respiratory System | B147: PM1171 | C147: CURB-65 Criteria
A148: Respiratory System | B148: PM1165 | C148: Types of Bronchiectasis
A149: Respiratory System | B149: PM1012 | C149: Pulmonary surfactant
A150: Respiratory System | B150: PM1010 | C150: Lung volumes and capacities
A151: Respiratory System | B151: PM1009 | C151: Acclimatization to high altitude
A152: Respiratory System | B152: PM1008 | C152: Characteristics of different types of Hypoxia
A153: Respiratory System | B153: PM0996 | C153: Factors affecting 2,3 -DPG
A154: Respiratory System | B154: PM0584 | C154: Chest X Ray signs in pulmonary embolism
A155: Respiratory System | B155: PM0581 | C155: Causes of predominantly unilateral pleural effusion
A156: Respiratory System | B156: PM0150 | C156: Typical Pneumonia v/s Atypical Pneumonia
... A188: Cardiovascular System | B188: PM1981 | C188: One-liners on Hypertrophic Cardiomyopathy (HCM)
A189: Cardiovascular System | B189: PM1977 | C189: Causes of CorPulmonale | D189: Respiratory System
A190: Cardiovascular System | B190: PM1846 | C190: The causes of holosystolic murmur are:
A191: Cardiovascular System | B191: PM1834 | C191: Cardiac conditions requiring antibiotic prophylaxis for infective endocarditis
A192: Cardiovascular System | B192: PM1738 | C192: Revised 2024 ESC Guidelines on Hypertension
A193: Cardiovascular System | B193: PM1679 | C193: CHADS2 VASc Score (Risk of stroke in AF)
...

Sheet Surgery
A1: Subtopic | B1: Pearl ID | C1: Pearl | D1: Also listed under | E1: Note
A2: General Surgery | B2: PM2499 | C2: ATLS Primary Survey | D2: Trauma
A3: General Surgery | B3: PM2498 | C3: Suture materials
A4: General Surgery | B4: PM2459 | C4: Suture materials
A5: General Surgery | B5: PM2294 | C5: Ankle-brachial Pressure Index (ABPI)
A6: General Surgery | B6: PM2292 | C6: CEAP Classification of Chronic Lower Extremity Venous Disease
A7: General Surgery | B7: PM2290 | C7: Colloid solution
A8: General Surgery | B8: PM2289 | C8: Estimating maintenance fluid requirement - Holliday Segar formula
A9: General Surgery | B9: PM2171 | C9: Color Coding of Intravenous Cannulae
A10: General Surgery | B10: PM2166 | C10: Complications of total parenteral nutrition
A11: General Surgery | B11: PM2147 | C11: Modified Gilbert's classification of hernia
A12: General Surgery | B12: PM2142 | C12: Complications of enteral nutrition
A13: General Surgery | B13: PM2124 | C13: Drugs that should be discontinued prior to surgery
A14: General Surgery | B14: PM2120 | C14: Brilliantly Transilluminating Swellings
... A27: General Surgery | B27: PM1512 | C27: Identification of Surgical Retractors
A28: General Surgery | B28: PM1500 | C28: Gurd's criteria for diagnosing fat embolism syndrome | D28: Trauma
A29: General Surgery | B29: PM1492 | C29: Complications of a Massive Transfusion
A30: General Surgery | B30: PM1486 | C30: Classification of hemorrhagic shock
A31: General Surgery | B31: PM1478 | C31: Malnutrition Universal Screening Tool (MUST)
A32: General Surgery | B32: PM1313 | C32: Idiopathic/Immune thrombocytopenic purpura (ITP)
A33: General Surgery | B33: PM1292 | C33: Length of various structures in the human body
A34: General Surgery | B34: PM1112 | C34: Marjolin’s Ulcer
A35: General Surgery | B35: PM1047 | C35: The triangle of pain/Electrical hazard zone:
A36: General Surgery | B36: PM0794 | C36: Types of microcalcification indicating malignancy
A37: General Surgery | B37: PM0787 | C37: Clinical signs and symptoms of phaeochromocytoma
A38: General Surgery | B38: PM0487 | C38: Degrees of Burns
A39: General Surgery | B39: PM0478 | C39: Surgical wound classifications as defined by CDC
A40: General Surgery | B40: PM0476 | C40: Staging of Pressure Sores
... A93: Gastrointestinal & Abdominal Surgery | B93: PM1609 | C93: Complications following Pancreaticoduodenectomy
A94: Gastrointestinal & Abdominal Surgery | B94: PM1608 | C94: Presenting symptoms of periampullary tumors of pancreas | D94: Pancreatic Surgery
A95: Gastrointestinal & Abdominal Surgery | B95: PM1603 | C95: Revised Model for End-stage liver disease (MELD) scoring system: MELD 3.0
A96: Gastrointestinal & Abdominal Surgery | B96: PM1602 | C96: Child-Turcotte-Pugh Score
A97: Gastrointestinal & Abdominal Surgery | B97: PM1597 | C97: Difference between pyogenic and amebic liver abscess
A98: Gastrointestinal & Abdominal Surgery | B98: PM1588 | C98: Barium studies in GI tuberculosis
A99: Gastrointestinal & Abdominal Surgery | B99: PM1586 | C99: Factors Preventing Spontaneous Fistula Closure
A100: Gastrointestinal & Abdominal Surgery | B100: PM1585 | C100: Rule of two’s in Meckel's diverticulum
A101: Gastrointestinal & Abdominal Surgery | B101: PM1580 | C101: Characteristic differentiating features of the jejunum and ileum
A102: Gastrointestinal & Abdominal Surgery | B102: PM1578 | C102: Replacement conduits after esophagectomy
A103: Gastrointestinal & Abdominal Surgery | B103: PM1576 | C103: Types of Fundoplication
A104: Gastrointestinal & Abdominal Surgery | B104: PM1575 | C104: Manometric classification of esophageal motility disorders | D104: Upper GI Surgery
...

Sheet Obstetrics and Gynaecology
A1: Subtopic | B1: Pearl ID | C1: Pearl | D1: Also listed under | E1: Note
A2: Fundamentals of Reproduction | B2: PM2366 | C2: Perineal Body
A3: Fundamentals of Reproduction | B3: PM2348 | C3: Homologous structures in male and female genitalia
A4: Fundamentals of Reproduction | B4: PM2338 | C4: Sexual Differentiation
A5: Fundamentals of Reproduction | B5: PM2182 | C5: Disorders of Sexual Development
A6: Fundamentals of Reproduction | B6: PM2104 | C6: Accessory Reproductive Glands in Male & Female
A7: Fundamentals of Reproduction | B7: PM1979 | C7: Derivatives of Mesonephric (Wolffian) duct and Paramesonephric (Mullerian) duct
A8: Fundamentals of Reproduction | B8: PM1912 | C8: Mullerian Anomalies
A9: Fundamentals of Reproduction | B9: PM1851 | C9: Fallopian tube
A10: Fundamentals of Reproduction | B10: PM1514 | C10: Hormonal Regulation of Menstrual Cycle
A11: Fundamentals of Reproduction | B11: PM1513 | C11: Events of Early Pregnancy
A12: Fundamentals of Reproduction | B12: PM1510 | C12: Biosynthesis Pathway for Androgen Synthesis
A13: Fundamentals of Reproduction | B13: PM1403 | C13: Fetal Skull Dimensions
... A53: Labor and Puerperium | B53: PM0041 | C53: Criteria for forceps delivery
A54: Labor and Puerperium | B54: PM0040 | C54: Obstetrics forceps | D54: Instruments
A55: Obstetric Complications | B55: PM2236 | C55: Twinning
A56: Obstetric Complications | B56: PM2225 | C56: Uses of Misoprostol
A57: Obstetric Complications | B57: PM2135 | C57: Radiological features of Intrauterine Death
A58: Obstetric Complications | B58: PM2131 | C58: Medical Termination of Pregnancy Act - MTP Act 1971
A59: Obstetric Complications | B59: PM1836 | C59: Twins
A60: Obstetric Complications | B60: PM1832 | C60: Complete vs. Partial Mole
A61: Obstetric Complications | B61: PM1829 | C61: Causes of oligohydramnios and polyhydramnios
A62: Obstetric Complications | B62: PM1822 | C62: Clinical classification of Spontaneous Abortion
A63: Obstetric Complications | B63: PM1441 | C63: Conditions Associated with Abnormal MSAFP
A64: Obstetric Complications | B64: PM1397 | C64: Indications of Amniotic Fluid Color
A65: Obstetric Complications | B65: PM1002 | C65: Contraindications to uterine artery embolization
A66: Medical and Surgical Complications in Pregnancy | B66: PM1003 | C66: Complications of pregnancy due to fibroids
... A128: Instruments | B128: PM2293 | C128: Instruments in OBG
A129: Instruments | B129: PM0040 | C129: Obstetrics forceps | D129: Labor and Puerperium
A130: Others | B130: PM2497 | C130: Uterine Signs in Pregnancy | E130: Title cut off in the screenshot; full title supplied by the user

Sheet Paediatrics
A1: Subtopic | B1: Pearl ID | C1: Pearl | D1: Also listed under | E1: Note
A2: Neonatology | B2: PM2490 | C2: Choice of initial feeding method in LBW infants
A3: Neonatology | B3: PM2394 | C3: A comprehensive list of factors that define an infant as being high risk
A4: Neonatology | B4: PM2213 | C4: Benign findings in a newborn
A5: Neonatology | B5: PM2195 | C5: APGAR score
A6: Neonatology | B6: PM2022 | C6: Teratogenic drugs and the birth defects
A7: Neonatology | B7: PM2021 | C7: Potential adverse reactions to drugs administered in infants
A8: Neonatology | B8: PM1828 | C8: Caput succedaneum and Cephalohematoma
A9: Neonatology | B9: PM1811 | C9: Timeline for primitive reflexes
A10: Neonatology | B10: PM1773 | C10: Baby-friendly hospital initiative (revised 2018)
A11: Growth and Development | B11: PM2090 | C11: Short stature: Familial vs Constitutional
A12: Growth and Development | B12: PM2037 | C12: Weight and height changes in children
A13: Growth and Development | B13: PM1946 | C13: Periods of growth
... A87: Paediatric Rheumatology | B87: PM0191 | C87: Kawasaki disease criteria
A88: Hematology | B88: PM2064 | C88: Thalassemia syndromes | E88: Partly cut off at the bottom of the screenshot

Sheet Orthopaedics
A1: Subtopic | B1: Pearl ID | C1: Pearl | D1: Also listed under | E1: Note
A2: Fracture and its complications | B2: PM2318 | C2: Bone grafts and substitutes
A3: Fracture and its complications | B3: PM2207 | C3: Acute Compartment and Crush Syndromes | D3: Complications of Fracture
A4: Fracture and its complications | B4: PM2164 | C4: Factors that impair bone healing and cause non-union | D4: Complications of Fracture
A5: Fracture and its complications | B5: PM2159 | C5: Orthopedic trauma and associated vascular injuries | D5: Upper Limb; Lower Limb
A6: Fracture and its complications | B6: PM2158 | C6: Fractures/dislocations and associated nerve injuries | D6: Upper Limb; Lower Limb; Nerve injuries
A7: Fracture and its complications | B7: PM2011 | C7: Plaster casts and their uses: | D7: Upper Limb
A8: Fracture and its complications | B8: PM1997 | C8: Gustilo and Anderson classification for open fracture
A9: Fracture and its complications | B9: PM1500 | C9: Gurd's criteria for diagnosing fat embolism syndrome
A10: Fracture and its complications | B10: PM0704 | C10: Types of Salter-Harris fractures- Mnemonic | D10: Upper Limb; Paediatric Orthopaedics
A11: Fracture and its complications | B11: PM0655 | C11: Pathological fracture
A12: Neck | B12: PM2041 | C12: Thoracic outlet syndrome and its tests:
A13: Neck | B13: PM0650 | C13: Torticollis
A14: Upper Limb | B14: PM2325 | C14: Methods of reduction of shoulder dislocation
A15: Upper Limb | B15: PM2324 | C15: Common dislocations at different joints | D15: Lower Limb
A16: Upper Limb | B16: PM2203 | C16: Important tests and signs to assess the function of rotator cuff muscles
A17: Upper Limb | B17: PM2159 | C17: Orthopedic trauma and associated vascular injuries | D17: Fracture and its complications; Lower Limb
A18: Upper Limb | B18: PM2158 | C18: Fractures/dislocations and associated nerve injuries | D18: Fracture and its complications; Lower Limb; Nerve injuries
A19: Upper Limb | B19: PM2125 | C19: Mechanisms of Injury around the elbow
A20: Upper Limb | B20: PM2053 | C20: Bursitis | D20: Lower Limb
A21: Upper Limb | B21: PM2052 | C21: Important conditions of the elbow:
A22: Upper Limb | B22: PM2033 | C22: Important Injuries of the Hand
A23: Upper Limb | B23: PM2016 | C23: Complications of Colle’s fracture:
A24: Upper Limb | B24: PM2015 | C24: Tension Band Wiring | D24: Lower Limb
A25: Upper Limb | B25: PM2014 | C25: Fractures of necessity | D25: Lower Limb
A26: Upper Limb | B26: PM2013 | C26: Three point bony relationship in elbow:
A27: Upper Limb | B27: PM2011 | C27: Plaster casts and their uses: | D27: Fracture and its complications
A28: Upper Limb | B28: PM2009 | C28: Tests for anterior shoulder dislocation
A29: Upper Limb | B29: PM2002 | C29: Dermatome of upper limb
A30: Upper Limb | B30: PM2001 | C30: Named classification systems for fractures and dislocations | D30: Lower Limb; Spine & Pelvis
A31: Upper Limb | B31: PM2000 | C31: Test for evaluation of glenohumeral joint instability in recurrent dislocation.
A32: Upper Limb | B32: PM1499 | C32: Compression neuropathies | D32: Lower Limb; Nerve injuries
A33: Upper Limb | B33: PM1418 | C33: Management of Pulseless Supracondylar Fracture | D33: Advanced Orthopaedics & Management
A34: Upper Limb | B34: PM1336 | C34: Common X-Ray views | D34: Lower Limb; Spine & Pelvis
A35: Upper Limb | B35: PM1099 | C35: Important angles used in the diagnosis of Orthopedic conditions | D35: Lower Limb; Spine & Pelvis
A36: Upper Limb | B36: PM0704 | C36: Types of Salter-Harris fractures- Mnemonic | D36: Fracture and its complications; Paediatric Orthopaedics
A37: Upper Limb | B37: PM0651 | C37: Medial and lateral epicondylitis
A38: Upper Limb | B38: PM0649 | C38: Named fractures of the upper limb
A39: Lower Limb | B39: PM2408 | C39: Anterior and posterior dislocation of the hip
A40: Lower Limb | B40: PM2324 | C40: Common dislocations at different joints | D40: Upper Limb
...

Sheet Dermatology
A1: Subtopic | B1: Pearl ID | C1: Pearl | D1: Also listed under | E1: Note
A2: The Skin | B2: PM1889 | C2: Colour of Skin and Fitzpatrick Classification of Skin types
A3: The Skin | B3: PM1880 | C3: Cells of the epidermis
A4: The Skin | B4: PM1875 | C4: Dermoepidermal Junction/Basement Membrane Zone
A5: Clinical Dermatology | B5: PM2213 | C5: Benign findings in a newborn
A6: Clinical Dermatology | B6: PM1962 | C6: Flowchart for Quick Diagnosis using Tzanck Smear Results
A7: Clinical Dermatology | B7: PM1961 | C7: Tzanck Smear in Dermatology
A8: Clinical Dermatology | B8: PM0366 | C8: Difference between classic and neonatal scabies
A9: Clinical Dermatology | B9: PM0260 | C9: Wood's lamp examination
A10: Clinical Dermatology | B10: PM0257 | C10: Primary and Secondary Lesions of Skin
A11: Clinical Dermatology | B11: PM0256 | C11: Shapes of skin lesions
A12: Clinical Dermatology | B12: PM0255 | C12: Glossary of important skin lesions
A13: Clinical Dermatology | B13: PM0248 | C13: Key Chart to help differentiate lesions on face
... A32: Papulosquamous Disorders | B32: PM0259 | C32: Types of scales associated with dermatological conditions
A33: Vesiculobullous Disorders | B33: PM2455 | C33: Skin and soft tissue lesions caused by Staphylococcus | D33: Skin Infections & Infestations
A34: Vesiculobullous Disorders | B34: PM2454 | C34: Skin and soft tissue lesions caused by Streptococcus | D34: Skin Infections & Infestations
A35: Vesiculobullous Disorders | B35: PM2085 | C35: Differences between pemphigus vulgaris and bullous pemphigoid
A36: Vesiculobullous Disorders | B36: PM0363 | C36: Classification of Vesiculobullous Disorders
A37: Vesiculobullous Disorders | B37: PM0224 | C37: Vesiculobullous Disorders
A38: Skin Infections & Infestations | B38: PM2455 | C38: Skin and soft tissue lesions caused by Staphylococcus | D38: Vesiculobullous Disorders
A39: Skin Infections & Infestations | B39: PM2454 | C39: Skin and soft tissue lesions caused by Streptococcus | D39: Vesiculobullous Disorders
A40: Skin Infections & Infestations | B40: PM1995 | C40: Nail changes in lichen planus
A41: Skin Infections & Infestations | B41: PM1994 | C41: Nail changes in psoriasis
A42: Skin Infections & Infestations | B42: PM1971 | C42: Classification of cutaneous tuberculosis
A43: Skin Infections & Infestations | B43: PM1967 | C43: Characteristics of Ridley Jopling Classification in Leprosy
A44: Skin Infections & Infestations | B44: PM1966 | C44: Lepra Reactions
A45: Skin Infections & Infestations | B45: PM0618 | C45: Skin rashes: 1st to 6th diseases
A46: Skin Infections & Infestations | B46: PM0615 | C46: Clinical manifestations of herpes simplex virus-1
A47: Skin Infections & Infestations | B47: PM0360 | C47: Cutaneous Infections/Diseases caused by Staphylococcus aureus
A48: Skin Infections & Infestations | B48: PM0359 | C48: Cutaneous Infections/Diseases caused by Streptococcus pyogenes
A49: Skin Infections & Infestations | B49: PM0342 | C49: Differentiating features between Tuberculoid Leprosy (TT) and Lepromatous Leprosy (LL)
A50: Skin Infections & Infestations | B50: PM0341 | C50: WHO proposed Multi Drug Therapy (MDT) for the treatment of Leprosy
A51: Sexually Transmitted Infections | B51: PM2456 | C51: Sexually transmitted infections
... A63: Skin in Systemic Disorders | B63: PM0297 | C63: Types of Psoriatic Arthritis

Sheet Psychiatry
A1: Subtopic | B1: Pearl ID | C1: Pearl | D1: Also listed under | E1: Note
A2: Facets of Psychiatry | B2: PM2314 | C2: Scientists and their contributions to psychiatry
A3: Facets of Psychiatry | B3: PM0826 | C3: Maslow's Hierarchy of Needs
A4: Facets of Psychiatry | B4: PM0353 | C4: Defense mechanisms that operate in various diseases
A5: Facets of Psychiatry | B5: PM0351 | C5: Defense mechanisms
A6: Facets of Psychiatry | B6: PM0346 | C6: Contributions by Sigmund Freud
A7: Clinical Psychiatry | B7: PM2418 | C7: Actions of antipsychotic drugs
A8: Clinical Psychiatry | B8: PM2415 | C8: Adverse effects of specific antidepressants
A9: Clinical Psychiatry | B9: PM2384 | C9: Classification of disorders of thought
A10: Clinical Psychiatry | B10: PM2383 | C10: Disorders of thought and perception
A11: Clinical Psychiatry | B11: PM2323 | C11: ECT versus TMS
A12: Clinical Psychiatry | B12: PM2116 | C12: Neurotransmitters
A13: Clinical Psychiatry | B13: PM2046 | C13: The Mental Health Care Act, 2017 and The Mental Health Act, 1987
... A74: Child Psychiatry | B74: PM2030 | C74: Speech sound disorder Vs Neurological/Structural dysarthria
A75: Forensic Psychiatry | B75: PM2059 | C75: BNS section 22, M'Naghten's rule | E75: Title cut off in the screenshot; completed from the same pearl in Forensic Medicine

Sheet Anaesthesia
A1: Subtopic | B1: Pearl ID | C1: Pearl | D1: Also listed under | E1: Note
A2: Preoperative evaluation and monitoring | B2: PM2230 | C2: Factors affecting End-tidal CO2 (ETCO2)
A3: Preoperative evaluation and monitoring | B3: PM2124 | C3: Drugs that should be discontinued prior to surgery
A4: Preoperative evaluation and monitoring | B4: PM2093 | C4: Drugs that can be continued on the day of surgery
A5: Preoperative evaluation and monitoring | B5: PM0413 | C5: Samsoon & Young's Modified Mallampati Classification
A6: Preoperative evaluation and monitoring | B6: PM0412 | C6: Predictors of Difficult Airway
A7: Preoperative evaluation and monitoring | B7: PM0411 | C7: American Society of Anesthesiologists’ Physical Status Classification of Patients
A8: Preoperative evaluation and monitoring | B8: PM0186 | C8: Various capnography waveforms:
A9: Preoperative evaluation and monitoring | B9: PM0181 | C9: A list of anaesthetics and their physiological effects
A10: Preoperative evaluation and monitoring | B10: PM0139 | C10: Stages of Anesthesia
A11: Airway management and resuscitation | B11: PM2494 | C11: Basic Life Support (BLS) Algorithm
A12: Airway management and resuscitation | B12: PM2295 | C12: High quality CPR for adults
A13: Airway management and resuscitation | B13: PM2290 | C13: Colloid solution
